<?xml version="1.0" encoding="utf-8" ?>
<!-- =================================================================================== -->
<!-- |    This document was autogenerated by xacro from /home/andrew/Desktop/unisa_robotic/ex2_transforms/src/fanuc_description/robot/fanuc_m20ia.xacro | -->
<!-- |    EDITING THIS FILE BY HAND IS NOT RECOMMENDED                                 | -->
<!-- =================================================================================== -->
<!-- 
    This URDF uses the Denavit-Hartenberg (DH) conventions to place the reference frames of the joints.
    It uses offsets to correctly place the visual and collision meshes. The Fanuc M10iA meshes are
    generated such that their reference frames' origins are always placed in a center of rotation.
    This allows to offset the visual and collision meshes by using only the displacements in the
    mechanical drawing, without the need for manual (and error-prone) adjustements.

    roslaunch urdf_tutorial display.launch model:=fanucM10iA.xacro
-->
<robot name="fanuc_m20ia">
    <!--************************************************BASE_LINK********************************************-->
    <link name="base_link">
        <!--link properties-->
        <!-- 
<inertial>

        </inertial>
 -->
        <visual>
            <origin rpy="0 0 0" xyz="0 0 0" />
            <geometry>
                <mesh filename="package://fanuc_description/fanuc_meshes/visual/link_0.dae" />
            </geometry>
            <material name="" />
        </visual>
        <collision>
            <origin rpy="0 0 0" xyz="0 0 0" />
            <geometry>
                <mesh filename="package://fanuc_description/fanuc_meshes/collision/link_0.stl" />
            </geometry>
        </collision>
        
<inertial>
            <mass value="0.1" />
            <inertia ixx="0.03" iyy="0.03" izz="0.03" ixy="0.0" ixz="0.0" iyz="0.0" />
        </inertial>

    </link>
    <!--************************************************LINK 1********************************************-->
    <link name="link1">
        <visual>
            <origin rpy="0 0 0" xyz="0 0 0" />
            <geometry>
                <mesh filename="package://fanuc_description/fanuc_meshes/visual/link_1.dae" />
            </geometry>
            <material name="" />
        </visual>
        <collision>
            <origin rpy="0 0 0" xyz="0 0 0" />
            <geometry>
                <mesh filename="package://fanuc_description/fanuc_meshes/collision/link_1.stl" />
            </geometry>
        </collision>
        
<inertial>
            <mass value="0.1" />
            <inertia ixx="0.03" iyy="0.03" izz="0.03" ixy="0.0" ixz="0.0" iyz="0.0" />
        </inertial>

    </link>
    <joint name="joint1" type="revolute">
        <!--Joint properties-->
        <origin rpy="0 0 0" xyz="0 0 0" />
        <parent link="base_link" />
        <child link="link1" />
        <axis xyz="0 0 1" />
        <limit effort="12" lower="-2.965" upper="2.965" velocity="3.4" />
    </joint>
    <!--************************************************LINK 2********************************************-->
    <link name="link2">
        <!--Link properties-->
        <!-- 
<inertial>
        </inertial>
 -->
        <visual>
            <origin rpy="1.57079632679 0 0" xyz="-0.15 0.525 0" />
            <geometry>
                <mesh filename="package://fanuc_description/fanuc_meshes/visual/link_2.dae" />
            </geometry>
            <material name="" />
        </visual>
        <collision>
            <origin rpy="1.57079632679 0 0" xyz="-0.15 0.525 0" />
            <geometry>
                <mesh filename="package://fanuc_description/fanuc_meshes/collision/link_2.stl" />
            </geometry>
        </collision>
        
<inertial>
            <mass value="0.1" />
            <inertia ixx="0.03" iyy="0.03" izz="0.03" ixy="0.0" ixz="0.0" iyz="0.0" />
        </inertial>

    </link>
    <joint name="joint2" type="revolute">
        <origin rpy="-1.57079632679 0 0" xyz="0.15 0 0.525" />
        <parent link="link1" />
        <child link="link2" />
        <axis xyz="0 0 1" />
        <limit effort="12" lower="-2.27" upper="2.27" velocity="3.05" />
    </joint>
    <!--************************************************LINK 3********************************************-->
    <link name="link3">
        <!-- 
<inertial>
        </inertial>
 -->
        <visual>
            <origin rpy="1.57079632679 0 1.57079632679" xyz="-1.315 -0.15 0" />
            <geometry>
                <mesh filename="package://fanuc_description/fanuc_meshes/visual/link_3.dae" />
            </geometry>
            <material name="" />
        </visual>
        <collision>
            <origin rpy="1.57079632679 0 1.57079632679" xyz="-1.315 -0.15 0" />
            <geometry>
                <mesh filename="package://fanuc_description/fanuc_meshes/collision/link_3.stl" />
            </geometry>
        </collision>
        
<inertial>
            <mass value="0.1" />
            <inertia ixx="0.03" iyy="0.03" izz="0.03" ixy="0.0" ixz="0.0" iyz="0.0" />
        </inertial>

    </link>
    <joint name="joint3" type="revolute">
        <origin rpy="0 0 -1.57079632679" xyz="0 -0.79 0" />
        <parent link="link2" />
        <child link="link3" />
        <axis xyz="0 0 1" />
        <limit effort="12" lower="-4" upper="4" velocity="3.14" />
    </joint>
    <!--************************************************LINK 4********************************************-->
    <link name="link4">
        <visual>
            <origin rpy="3.14159265359 -1.57079632679 0" xyz="-1.465 0 -0.15" />
            <geometry>
                <mesh filename="package://fanuc_description/fanuc_meshes/visual/link_4.dae" />
            </geometry>
            <material name="" />
        </visual>
        <collision>
            <origin rpy="3.14159265359 -1.57079632679 0" xyz="-1.465 0 -0.15" />
            <geometry>
                <mesh filename="package://fanuc_description/fanuc_meshes/collision/link_4.stl" />
            </geometry>
        </collision>
        
<inertial>
            <mass value="0.1" />
            <inertia ixx="0.03" iyy="0.03" izz="0.03" ixy="0.0" ixz="0.0" iyz="0.0" />
        </inertial>

    </link>
    <joint name="joint4" type="revolute">
        <origin rpy="-1.57079632679 0 0" xyz="0.15 0 0" />
        <parent link="link3" />
        <child link="link4" />
        <axis xyz="0 0 1" />
        <limit effort="12" lower="-3.49" upper="3.49" velocity="7.07" />
    </joint>
    <!--************************************************LINK 5********************************************-->
    <link name="link5">
        <visual>
            <origin rpy="1.57079632679 0 1.57079632679" xyz="-1.465 -1.01 0" />
            <geometry>
                <mesh filename="package://fanuc_description/fanuc_meshes/visual/link_5.dae" />
            </geometry>
            <material name="" />
        </visual>
        <collision>
            <origin rpy="1.57079632679 0 1.57079632679" xyz="-1.465 -1.01 0" />
            <geometry>
                <mesh filename="package://fanuc_description/fanuc_meshes/collision/link_5.stl" />
            </geometry>
        </collision>
        
<inertial>
            <mass value="0.1" />
            <inertia ixx="0.03" iyy="0.03" izz="0.03" ixy="0.0" ixz="0.0" iyz="0.0" />
        </inertial>

    </link>
    <joint name="joint5" type="revolute">
        <origin rpy="1.57079632679 0 0" xyz="0 0 0.86" />
        <parent link="link4" />
        <child link="link5" />
        <axis xyz="0 0 1" />
        <limit effort="12" lower="-2.445" upper="2.445" velocity="7.07" />
    </joint>
    <!--************************************************LINK 6********************************************-->
    <link name="link6">
        <visual>
            <origin rpy="0 0 0" xyz="0 0 0" />
            <geometry>
                <mesh filename="package://fanuc_description/fanuc_meshes/visual/link_6.dae" />
            </geometry>
            <material name="" />
        </visual>
        <collision>
            <origin rpy="0 0 0" xyz="0 0 0" />
            <geometry>
                <mesh filename="package://fanuc_description/fanuc_meshes/collision/link_6.stl" />
            </geometry>
        </collision>
        
<inertial>
            <mass value="0.1" />
            <inertia ixx="0.03" iyy="0.03" izz="0.03" ixy="0.0" ixz="0.0" iyz="0.0" />
        </inertial>

    </link>
    <joint name="joint6" type="revolute">
        <!--Joint properties-->
        <origin rpy="-1.57079632679 0 0" xyz="0 0.1 0" />
        <parent link="link5" />
        <child link="link6" />
        <axis xyz="0 0 1" />
        <limit effort="12" lower="-7.855" upper="7.855" velocity="10.73" />
    </joint>
    <!--************************************************FLANGE********************************************-->
    <link name="flange" />
    <joint name="flange" type="fixed">
        <!--Joint properties-->
        <origin rpy="0 0 0" xyz="0 0 0" />
        <parent link="link6" />
        <child link="flange" />
    </joint>
    
<transmission name="trans_joint1">
        <type>transmission_interface/SimpleTransmission</type>
        <joint name="joint1">
            <hardwareInterface>hardware_interface/EffortJointInterface</hardwareInterface>
        </joint>
        <actuator name="joint1_motor">
            <hardwareInterface>hardware_interface/EffortJointInterface</hardwareInterface>
            <mechanicalReduction>1</mechanicalReduction>
        </actuator>
    </transmission>
    <transmission name="trans_joint2">
        <type>transmission_interface/SimpleTransmission</type>
        <joint name="joint2">
            <hardwareInterface>hardware_interface/EffortJointInterface</hardwareInterface>
        </joint>
        <actuator name="joint2_motor">
            <hardwareInterface>hardware_interface/EffortJointInterface</hardwareInterface>
            <mechanicalReduction>1</mechanicalReduction>
        </actuator>
    </transmission>
    <transmission name="trans_joint3">
        <type>transmission_interface/SimpleTransmission</type>
        <joint name="joint3">
            <hardwareInterface>hardware_interface/EffortJointInterface</hardwareInterface>
        </joint>
        <actuator name="joint3_motor">
            <hardwareInterface>hardware_interface/EffortJointInterface</hardwareInterface>
            <mechanicalReduction>1</mechanicalReduction>
        </actuator>
    </transmission>
    <transmission name="trans_joint4">
        <type>transmission_interface/SimpleTransmission</type>
        <joint name="joint4">
            <hardwareInterface>hardware_interface/EffortJointInterface</hardwareInterface>
        </joint>
        <actuator name="joint4_motor">
            <hardwareInterface>hardware_interface/EffortJointInterface</hardwareInterface>
            <mechanicalReduction>1</mechanicalReduction>
        </actuator>
    </transmission>
    <transmission name="trans_joint5">
        <type>transmission_interface/SimpleTransmission</type>
        <joint name="joint5">
            <hardwareInterface>hardware_interface/EffortJointInterface</hardwareInterface>
        </joint>
        <actuator name="joint5_motor">
            <hardwareInterface>hardware_interface/EffortJointInterface</hardwareInterface>
            <mechanicalReduction>1</mechanicalReduction>
        </actuator>
    </transmission>
    <transmission name="trans_joint6">
        <type>transmission_interface/SimpleTransmission</type>
        <joint name="joint6">
            <hardwareInterface>hardware_interface/EffortJointInterface</hardwareInterface>
        </joint>
        <actuator name="joint6_motor">
            <hardwareInterface>hardware_interface/EffortJointInterface</hardwareInterface>
            <mechanicalReduction>1</mechanicalReduction>
        </actuator>
    </transmission>
    <gazebo>
        <plugin name="gazebo_ros_control" filename="libgazebo_ros_control.so">
            <robotNamespace>/</robotNamespace>
        </plugin>
    </gazebo>
</robot>